2025-06-26 22:10:07,322 - __main__ - CRITICAL = 프로그램 오류
Traceback (most recent call last):
  File "C:\Users\neira\Desktop\파이썬추가수업\contact.py", line 137, in <module>
    contact = Contact('홍길동', '010-1234-5678', 'gildong@naver.com')
              ~~~~~~~^^^^^^^^^^^^^^^^^^^^^^^^^^^^^^^^^^^^^^^^^^^^^^^^
  File "C:\Users\neira\Desktop\파이썬추가수업\contact.py", line 22, in __init__
    self.phone = self.validate_phone(phone)
                 ~~~~~~~~~~~~~~~~~~~^^^^^^^
  File "C:\Users\neira\Desktop\파이썬추가수업\contact.py", line 29, in validate_phone
    if not re.mathch(pattern, phone):
           ^^^^^^^^^
AttributeError: module 're' has no attribute 'mathch'. Did you mean: 'match'?
2025-06-26 22:10:29,106 - __main__ - CRITICAL = 프로그램 오류
Traceback (most recent call last):
  File "C:\Users\neira\Desktop\파이썬추가수업\contact.py", line 141, in <module>
    for c in results:
             ^^^^^^^
TypeError: 'NoneType' object is not iterable
2025-06-26 22:17:00,861 - __main__ - INFO = 연락처가 추가되었습니다: 홍길동
2025-06-26 22:17:00,863 - __main__ - ERROR = 백업 생성에 실패했습니다: unknown encoding: tuf-8
Traceback (most recent call last):
  File "C:\Users\neira\Desktop\파이썬추가수업\contact.py", line 114, in backup
    with open(backup_file, 'w', encoding='tuf-8') as f:
         ~~~~^^^^^^^^^^^^^^^^^^^^^^^^^^^^^^^^^^^^
LookupError: unknown encoding: tuf-8
2025-06-26 22:17:00,877 - __main__ - CRITICAL = 프로그램 오류
Traceback (most recent call last):
  File "C:\Users\neira\Desktop\파이썬추가수업\contact.py", line 77, in save
    json.dum(data, f, ensure_ascii=False, indent=2)
    ^^^^^^^^
AttributeError: module 'json' has no attribute 'dum'. Did you mean: 'dump'?

During handling of the above exception, another exception occurred:

Traceback (most recent call last):
  File "C:\Users\neira\Desktop\파이썬추가수업\contact.py", line 138, in <module>
    book.add_contact(contact)
    ~~~~~~~~~~~~~~~~^^^^^^^^^
  File "C:\Users\neira\Desktop\파이썬추가수업\contact.py", line 60, in add_contact
    self.save()
    ~~~~~~~~~^^
  File "C:\Users\neira\Desktop\파이썬추가수업\contact.py", line 80, in save
    logger.error(f"저장에 실패했습니다: {e}", exe_info=True)
    ~~~~~~~~~~~~^^^^^^^^^^^^^^^^^^^^^^^^^^^^^^^^^^^^^^^^^^^^
  File "C:\Users\neira\AppData\Local\Programs\Python\Python313\Lib\logging\__init__.py", line 1551, in error
    self._log(ERROR, msg, args, **kwargs)
    ~~~~~~~~~^^^^^^^^^^^^^^^^^^^^^^^^^^^^
TypeError: Logger._log() got an unexpected keyword argument 'exe_info'. Did you mean 'exc_info'?
2025-06-26 22:17:19,858 - __main__ - ERROR = 파일 로드에 실패했습니다: Expecting value: line 1 column 1 (char 0)
Traceback (most recent call last):
  File "C:\Users\neira\Desktop\파이썬추가수업\contact.py", line 90, in load
    data = json.load(f)
  File "C:\Users\neira\AppData\Local\Programs\Python\Python313\Lib\json\__init__.py", line 293, in load
    return loads(fp.read(),
        cls=cls, object_hook=object_hook,
        parse_float=parse_float, parse_int=parse_int,
        parse_constant=parse_constant, object_pairs_hook=object_pairs_hook, **kw)
  File "C:\Users\neira\AppData\Local\Programs\Python\Python313\Lib\json\__init__.py", line 346, in loads
    return _default_decoder.decode(s)
           ~~~~~~~~~~~~~~~~~~~~~~~^^^
  File "C:\Users\neira\AppData\Local\Programs\Python\Python313\Lib\json\decoder.py", line 345, in decode
    obj, end = self.raw_decode(s, idx=_w(s, 0).end())
               ~~~~~~~~~~~~~~~^^^^^^^^^^^^^^^^^^^^^^^
  File "C:\Users\neira\AppData\Local\Programs\Python\Python313\Lib\json\decoder.py", line 363, in raw_decode
    raise JSONDecodeError("Expecting value", s, err.value) from None
json.decoder.JSONDecodeError: Expecting value: line 1 column 1 (char 0)
2025-06-26 22:17:19,871 - __main__ - INFO = 연락처가 추가되었습니다: 홍길동
2025-06-26 22:17:19,872 - __main__ - ERROR = 백업 생성에 실패했습니다: unknown encoding: tuf-8
Traceback (most recent call last):
  File "C:\Users\neira\Desktop\파이썬추가수업\contact.py", line 114, in backup
    with open(backup_file, 'w', encoding='tuf-8') as f:
         ~~~~^^^^^^^^^^^^^^^^^^^^^^^^^^^^^^^^^^^^
LookupError: unknown encoding: tuf-8
2025-06-26 22:17:19,873 - __main__ - ERROR = 저장에 실패했습니다: module 'json' has no attribute 'dum'
Traceback (most recent call last):
  File "C:\Users\neira\Desktop\파이썬추가수업\contact.py", line 77, in save
    json.dum(data, f, ensure_ascii=False, indent=2)
    ^^^^^^^^
AttributeError: module 'json' has no attribute 'dum'. Did you mean: 'dump'?
2025-06-26 22:17:19,874 - __main__ - CRITICAL = 프로그램 오류
Traceback (most recent call last):
  File "C:\Users\neira\Desktop\파이썬추가수업\contact.py", line 138, in <module>
    book.add_contact(contact)
    ~~~~~~~~~~~~~~~~^^^^^^^^^
  File "C:\Users\neira\Desktop\파이썬추가수업\contact.py", line 60, in add_contact
    self.save()
    ~~~~~~~~~^^
  File "C:\Users\neira\Desktop\파이썬추가수업\contact.py", line 77, in save
    json.dum(data, f, ensure_ascii=False, indent=2)
    ^^^^^^^^
AttributeError: module 'json' has no attribute 'dum'. Did you mean: 'dump'?
2025-06-26 22:17:37,918 - __main__ - ERROR = 파일 로드에 실패했습니다: Expecting value: line 1 column 1 (char 0)
Traceback (most recent call last):
  File "C:\Users\neira\Desktop\파이썬추가수업\contact.py", line 90, in load
    data = json.load(f)
  File "C:\Users\neira\AppData\Local\Programs\Python\Python313\Lib\json\__init__.py", line 293, in load
    return loads(fp.read(),
        cls=cls, object_hook=object_hook,
        parse_float=parse_float, parse_int=parse_int,
        parse_constant=parse_constant, object_pairs_hook=object_pairs_hook, **kw)
  File "C:\Users\neira\AppData\Local\Programs\Python\Python313\Lib\json\__init__.py", line 346, in loads
    return _default_decoder.decode(s)
           ~~~~~~~~~~~~~~~~~~~~~~~^^^
  File "C:\Users\neira\AppData\Local\Programs\Python\Python313\Lib\json\decoder.py", line 345, in decode
    obj, end = self.raw_decode(s, idx=_w(s, 0).end())
               ~~~~~~~~~~~~~~~^^^^^^^^^^^^^^^^^^^^^^^
  File "C:\Users\neira\AppData\Local\Programs\Python\Python313\Lib\json\decoder.py", line 363, in raw_decode
    raise JSONDecodeError("Expecting value", s, err.value) from None
json.decoder.JSONDecodeError: Expecting value: line 1 column 1 (char 0)
2025-06-26 22:17:37,922 - __main__ - INFO = 연락처가 추가되었습니다: 홍길동
2025-06-26 22:17:37,933 - __main__ - ERROR = 백업 생성에 실패했습니다: unknown encoding: tuf-8
Traceback (most recent call last):
  File "C:\Users\neira\Desktop\파이썬추가수업\contact.py", line 114, in backup
    with open(backup_file, 'w', encoding='tuf-8') as f:
         ~~~~^^^^^^^^^^^^^^^^^^^^^^^^^^^^^^^^^^^^
LookupError: unknown encoding: tuf-8
2025-06-26 22:17:37,934 - __main__ - INFO = 저장을 완료했습니다: 1개의 연락처
